nohup: ignoring input
INFO:     Started server process [216550]
INFO:     Waiting for application startup.
INFO:     Application startup complete.
INFO:     Uvicorn running on http://0.0.0.0:8003 (Press CTRL+C to quit)
INFO:     45.219.240.167:52725 - "GET /dashboard HTTP/1.1" 500 Internal Server Error
ERROR:    Exception in ASGI application
Traceback (most recent call last):
  File "/var/www/dns-management/DNS-management/venv/lib/python3.10/site-packages/uvicorn/protocols/http/httptools_impl.py", line 409, in run_asgi
    result = await app(  # type: ignore[func-returns-value]
  File "/var/www/dns-management/DNS-management/venv/lib/python3.10/site-packages/uvicorn/middleware/proxy_headers.py", line 60, in __call__
    return await self.app(scope, receive, send)
  File "/var/www/dns-management/DNS-management/venv/lib/python3.10/site-packages/fastapi/applications.py", line 1133, in __call__
    await super().__call__(scope, receive, send)
  File "/var/www/dns-management/DNS-management/venv/lib/python3.10/site-packages/starlette/applications.py", line 113, in __call__
    await self.middleware_stack(scope, receive, send)
  File "/var/www/dns-management/DNS-management/venv/lib/python3.10/site-packages/starlette/middleware/errors.py", line 186, in __call__
    raise exc
  File "/var/www/dns-management/DNS-management/venv/lib/python3.10/site-packages/starlette/middleware/errors.py", line 164, in __call__
    await self.app(scope, receive, _send)
  File "/var/www/dns-management/DNS-management/venv/lib/python3.10/site-packages/starlette/middleware/sessions.py", line 85, in __call__
    await self.app(scope, receive, send_wrapper)
  File "/var/www/dns-management/DNS-management/venv/lib/python3.10/site-packages/starlette/middleware/exceptions.py", line 63, in __call__
    await wrap_app_handling_exceptions(self.app, conn)(scope, receive, send)
  File "/var/www/dns-management/DNS-management/venv/lib/python3.10/site-packages/starlette/_exception_handler.py", line 53, in wrapped_app
    raise exc
  File "/var/www/dns-management/DNS-management/venv/lib/python3.10/site-packages/starlette/_exception_handler.py", line 42, in wrapped_app
    await app(scope, receive, sender)
  File "/var/www/dns-management/DNS-management/venv/lib/python3.10/site-packages/fastapi/middleware/asyncexitstack.py", line 18, in __call__
    await self.app(scope, receive, send)
  File "/var/www/dns-management/DNS-management/venv/lib/python3.10/site-packages/starlette/routing.py", line 716, in __call__
    await self.middleware_stack(scope, receive, send)
  File "/var/www/dns-management/DNS-management/venv/lib/python3.10/site-packages/starlette/routing.py", line 736, in app
    await route.handle(scope, receive, send)
  File "/var/www/dns-management/DNS-management/venv/lib/python3.10/site-packages/starlette/routing.py", line 290, in handle
    await self.app(scope, receive, send)
  File "/var/www/dns-management/DNS-management/venv/lib/python3.10/site-packages/fastapi/routing.py", line 123, in app
    await wrap_app_handling_exceptions(app, request)(scope, receive, send)
  File "/var/www/dns-management/DNS-management/venv/lib/python3.10/site-packages/starlette/_exception_handler.py", line 53, in wrapped_app
    raise exc
  File "/var/www/dns-management/DNS-management/venv/lib/python3.10/site-packages/starlette/_exception_handler.py", line 42, in wrapped_app
    await app(scope, receive, sender)
  File "/var/www/dns-management/DNS-management/venv/lib/python3.10/site-packages/fastapi/routing.py", line 109, in app
    response = await f(request)
  File "/var/www/dns-management/DNS-management/venv/lib/python3.10/site-packages/fastapi/routing.py", line 389, in app
    raw_response = await run_endpoint_function(
  File "/var/www/dns-management/DNS-management/venv/lib/python3.10/site-packages/fastapi/routing.py", line 288, in run_endpoint_function
    return await dependant.call(**values)
  File "/var/www/dns-management/DNS-management/routes.py", line 91, in dashboard
    return templates.TemplateResponse("dashboard.html", {
  File "/var/www/dns-management/DNS-management/venv/lib/python3.10/site-packages/starlette/templating.py", line 210, in TemplateResponse
    return _TemplateResponse(
  File "/var/www/dns-management/DNS-management/venv/lib/python3.10/site-packages/starlette/templating.py", line 41, in __init__
    content = template.render(context)
  File "/var/www/dns-management/DNS-management/venv/lib/python3.10/site-packages/jinja2/environment.py", line 1295, in render
    self.environment.handle_exception()
  File "/var/www/dns-management/DNS-management/venv/lib/python3.10/site-packages/jinja2/environment.py", line 942, in handle_exception
    raise rewrite_traceback_stack(source=source)
  File "templates/dashboard.html", line 1, in top-level template code
    {% extends "base.html" %}
  File "templates/base.html", line 44, in top-level template code
    {% if current_user.is_admin %}
  File "/var/www/dns-management/DNS-management/venv/lib/python3.10/site-packages/jinja2/environment.py", line 490, in getattr
    return getattr(obj, attribute)
jinja2.exceptions.UndefinedError: 'current_user' is undefined
INFO:     45.219.240.167:61842 - "GET / HTTP/1.1" 200 OK
INFO:     45.219.240.167:52914 - "POST /login HTTP/1.1" 302 Found
INFO:     45.219.240.167:52914 - "GET /dashboard HTTP/1.1" 500 Internal Server Error
ERROR:    Exception in ASGI application
Traceback (most recent call last):
  File "/var/www/dns-management/DNS-management/venv/lib/python3.10/site-packages/uvicorn/protocols/http/httptools_impl.py", line 409, in run_asgi
    result = await app(  # type: ignore[func-returns-value]
  File "/var/www/dns-management/DNS-management/venv/lib/python3.10/site-packages/uvicorn/middleware/proxy_headers.py", line 60, in __call__
    return await self.app(scope, receive, send)
  File "/var/www/dns-management/DNS-management/venv/lib/python3.10/site-packages/fastapi/applications.py", line 1133, in __call__
    await super().__call__(scope, receive, send)
  File "/var/www/dns-management/DNS-management/venv/lib/python3.10/site-packages/starlette/applications.py", line 113, in __call__
    await self.middleware_stack(scope, receive, send)
  File "/var/www/dns-management/DNS-management/venv/lib/python3.10/site-packages/starlette/middleware/errors.py", line 186, in __call__
    raise exc
  File "/var/www/dns-management/DNS-management/venv/lib/python3.10/site-packages/starlette/middleware/errors.py", line 164, in __call__
    await self.app(scope, receive, _send)
  File "/var/www/dns-management/DNS-management/venv/lib/python3.10/site-packages/starlette/middleware/sessions.py", line 85, in __call__
    await self.app(scope, receive, send_wrapper)
  File "/var/www/dns-management/DNS-management/venv/lib/python3.10/site-packages/starlette/middleware/exceptions.py", line 63, in __call__
    await wrap_app_handling_exceptions(self.app, conn)(scope, receive, send)
  File "/var/www/dns-management/DNS-management/venv/lib/python3.10/site-packages/starlette/_exception_handler.py", line 53, in wrapped_app
    raise exc
  File "/var/www/dns-management/DNS-management/venv/lib/python3.10/site-packages/starlette/_exception_handler.py", line 42, in wrapped_app
    await app(scope, receive, sender)
  File "/var/www/dns-management/DNS-management/venv/lib/python3.10/site-packages/fastapi/middleware/asyncexitstack.py", line 18, in __call__
    await self.app(scope, receive, send)
  File "/var/www/dns-management/DNS-management/venv/lib/python3.10/site-packages/starlette/routing.py", line 716, in __call__
    await self.middleware_stack(scope, receive, send)
  File "/var/www/dns-management/DNS-management/venv/lib/python3.10/site-packages/starlette/routing.py", line 736, in app
    await route.handle(scope, receive, send)
  File "/var/www/dns-management/DNS-management/venv/lib/python3.10/site-packages/starlette/routing.py", line 290, in handle
    await self.app(scope, receive, send)
  File "/var/www/dns-management/DNS-management/venv/lib/python3.10/site-packages/fastapi/routing.py", line 123, in app
    await wrap_app_handling_exceptions(app, request)(scope, receive, send)
  File "/var/www/dns-management/DNS-management/venv/lib/python3.10/site-packages/starlette/_exception_handler.py", line 53, in wrapped_app
    raise exc
  File "/var/www/dns-management/DNS-management/venv/lib/python3.10/site-packages/starlette/_exception_handler.py", line 42, in wrapped_app
    await app(scope, receive, sender)
  File "/var/www/dns-management/DNS-management/venv/lib/python3.10/site-packages/fastapi/routing.py", line 109, in app
    response = await f(request)
  File "/var/www/dns-management/DNS-management/venv/lib/python3.10/site-packages/fastapi/routing.py", line 389, in app
    raw_response = await run_endpoint_function(
  File "/var/www/dns-management/DNS-management/venv/lib/python3.10/site-packages/fastapi/routing.py", line 288, in run_endpoint_function
    return await dependant.call(**values)
  File "/var/www/dns-management/DNS-management/routes.py", line 91, in dashboard
    return templates.TemplateResponse("dashboard.html", {
  File "/var/www/dns-management/DNS-management/venv/lib/python3.10/site-packages/starlette/templating.py", line 210, in TemplateResponse
    return _TemplateResponse(
  File "/var/www/dns-management/DNS-management/venv/lib/python3.10/site-packages/starlette/templating.py", line 41, in __init__
    content = template.render(context)
  File "/var/www/dns-management/DNS-management/venv/lib/python3.10/site-packages/jinja2/environment.py", line 1295, in render
    self.environment.handle_exception()
  File "/var/www/dns-management/DNS-management/venv/lib/python3.10/site-packages/jinja2/environment.py", line 942, in handle_exception
    raise rewrite_traceback_stack(source=source)
  File "templates/dashboard.html", line 1, in top-level template code
    {% extends "base.html" %}
  File "templates/base.html", line 44, in top-level template code
    {% if current_user.is_admin %}
  File "/var/www/dns-management/DNS-management/venv/lib/python3.10/site-packages/jinja2/environment.py", line 490, in getattr
    return getattr(obj, attribute)
jinja2.exceptions.UndefinedError: 'current_user' is undefined
INFO:     Shutting down
INFO:     Waiting for application shutdown.
INFO:     Application shutdown complete.
INFO:     Finished server process [216550]
